[2023-08-23T09:31:47.119+0000] {taskinstance.py:1159} INFO - Dependencies all met for dep_context=non-requeueable deps ti=<TaskInstance: dag_with_taskflow_api_v02.greet scheduled__2022-06-23T00:00:00+00:00 [queued]>
[2023-08-23T09:31:47.147+0000] {taskinstance.py:1159} INFO - Dependencies all met for dep_context=requeueable deps ti=<TaskInstance: dag_with_taskflow_api_v02.greet scheduled__2022-06-23T00:00:00+00:00 [queued]>
[2023-08-23T09:31:47.148+0000] {taskinstance.py:1361} INFO - Starting attempt 4 of 6
[2023-08-23T09:46:26.567+0000] {taskinstance.py:1382} INFO - Executing <Task(_PythonDecoratedOperator): greet> on 2022-06-23 00:00:00+00:00
[2023-08-23T09:46:26.580+0000] {standard_task_runner.py:57} INFO - Started process 5049 to run task
[2023-08-23T09:46:26.593+0000] {standard_task_runner.py:84} INFO - Running: ['***', 'tasks', 'run', 'dag_with_taskflow_api_v02', 'greet', 'scheduled__2022-06-23T00:00:00+00:00', '--job-id', '13297', '--raw', '--subdir', 'DAGS_FOLDER/dag_with_taskflow_api.py', '--cfg-path', '/tmp/tmpmhfj7y6l']
[2023-08-23T09:46:26.597+0000] {standard_task_runner.py:85} INFO - Job 13297: Subtask greet
[2023-08-23T09:46:26.715+0000] {task_command.py:415} INFO - Running <TaskInstance: dag_with_taskflow_api_v02.greet scheduled__2022-06-23T00:00:00+00:00 [running]> on host b0ce6883e4a1
[2023-08-23T09:46:26.968+0000] {taskinstance.py:1660} INFO - Exporting env vars: AIRFLOW_CTX_DAG_OWNER='Techquier' AIRFLOW_CTX_DAG_ID='dag_with_taskflow_api_v02' AIRFLOW_CTX_TASK_ID='greet' AIRFLOW_CTX_EXECUTION_DATE='2022-06-23T00:00:00+00:00' AIRFLOW_CTX_TRY_NUMBER='4' AIRFLOW_CTX_DAG_RUN_ID='scheduled__2022-06-23T00:00:00+00:00'
[2023-08-23T09:46:26.970+0000] {taskinstance.py:1943} ERROR - Task failed with exception
Traceback (most recent call last):
  File "/home/airflow/.local/lib/python3.8/site-packages/airflow/decorators/base.py", line 221, in execute
    return_value = super().execute(context)
  File "/home/airflow/.local/lib/python3.8/site-packages/airflow/operators/python.py", line 192, in execute
    return_value = self.execute_callable()
  File "/home/airflow/.local/lib/python3.8/site-packages/airflow/operators/python.py", line 209, in execute_callable
    return self.python_callable(*self.op_args, **self.op_kwargs)
  File "/opt/airflow/dags/dag_with_taskflow_api.py", line 29, in greet
    print(f"Hello world! My name is {first_namename}{last_name}"
NameError: name 'first_namename' is not defined
[2023-08-23T09:46:26.999+0000] {taskinstance.py:1400} INFO - Marking task as UP_FOR_RETRY. dag_id=dag_with_taskflow_api_v02, task_id=greet, execution_date=20220623T000000, start_date=20230823T093147, end_date=20230823T094626
[2023-08-23T09:46:27.021+0000] {standard_task_runner.py:104} ERROR - Failed to execute job 13297 for task greet (name 'first_namename' is not defined; 5049)
[2023-08-23T09:46:27.034+0000] {local_task_job_runner.py:228} INFO - Task exited with return code 1
[2023-08-23T09:46:27.095+0000] {taskinstance.py:2784} INFO - 0 downstream tasks scheduled from follow-on schedule check
