[2023-08-22T05:20:08.694+0000] {taskinstance.py:1159} INFO - Dependencies all met for dep_context=non-requeueable deps ti=<TaskInstance: our_dag_with_python_opearator_v04.greet scheduled__2021-10-09T00:00:00+00:00 [queued]>
[2023-08-22T05:20:08.710+0000] {taskinstance.py:1159} INFO - Dependencies all met for dep_context=requeueable deps ti=<TaskInstance: our_dag_with_python_opearator_v04.greet scheduled__2021-10-09T00:00:00+00:00 [queued]>
[2023-08-22T05:20:08.712+0000] {taskinstance.py:1361} INFO - Starting attempt 1 of 6
[2023-08-22T05:20:08.747+0000] {taskinstance.py:1382} INFO - Executing <Task(PythonOperator): greet> on 2021-10-09 00:00:00+00:00
[2023-08-22T05:20:08.755+0000] {standard_task_runner.py:57} INFO - Started process 17039 to run task
[2023-08-22T05:20:08.760+0000] {standard_task_runner.py:84} INFO - Running: ['***', 'tasks', 'run', 'our_dag_with_python_opearator_v04', 'greet', 'scheduled__2021-10-09T00:00:00+00:00', '--job-id', '5302', '--raw', '--subdir', 'DAGS_FOLDER/create_dag_with_python_operator.py', '--cfg-path', '/tmp/tmpyxdd5wy9']
[2023-08-22T05:20:08.763+0000] {standard_task_runner.py:85} INFO - Job 5302: Subtask greet
[2023-08-22T05:20:08.836+0000] {task_command.py:415} INFO - Running <TaskInstance: our_dag_with_python_opearator_v04.greet scheduled__2021-10-09T00:00:00+00:00 [running]> on host b0ce6883e4a1
[2023-08-22T05:20:08.936+0000] {taskinstance.py:1660} INFO - Exporting env vars: AIRFLOW_CTX_DAG_OWNER='coder2j' AIRFLOW_CTX_DAG_ID='our_dag_with_python_opearator_v04' AIRFLOW_CTX_TASK_ID='greet' AIRFLOW_CTX_EXECUTION_DATE='2021-10-09T00:00:00+00:00' AIRFLOW_CTX_TRY_NUMBER='1' AIRFLOW_CTX_DAG_RUN_ID='scheduled__2021-10-09T00:00:00+00:00'
[2023-08-22T05:20:08.939+0000] {taskinstance.py:1943} ERROR - Task failed with exception
Traceback (most recent call last):
  File "/home/airflow/.local/lib/python3.8/site-packages/airflow/operators/python.py", line 192, in execute
    return_value = self.execute_callable()
  File "/home/airflow/.local/lib/python3.8/site-packages/airflow/operators/python.py", line 209, in execute_callable
    return self.python_callable(*self.op_args, **self.op_kwargs)
  File "/opt/airflow/dags/create_dag_with_python_operator.py", line 11, in greet
    name = ti.xcoms_pull(task_ids='get_name')
AttributeError: 'TaskInstance' object has no attribute 'xcoms_pull'
[2023-08-22T05:20:08.961+0000] {taskinstance.py:1400} INFO - Marking task as UP_FOR_RETRY. dag_id=our_dag_with_python_opearator_v04, task_id=greet, execution_date=20211009T000000, start_date=20230822T052008, end_date=20230822T052008
[2023-08-22T05:20:08.980+0000] {standard_task_runner.py:104} ERROR - Failed to execute job 5302 for task greet ('TaskInstance' object has no attribute 'xcoms_pull'; 17039)
[2023-08-22T05:20:09.014+0000] {local_task_job_runner.py:228} INFO - Task exited with return code 1
[2023-08-22T05:20:09.069+0000] {taskinstance.py:2784} INFO - 0 downstream tasks scheduled from follow-on schedule check
