[2023-08-22T16:08:55.945+0000] {taskinstance.py:1159} INFO - Dependencies all met for dep_context=non-requeueable deps ti=<TaskInstance: dag_with_taskflow_api_v02.greet scheduled__2022-01-26T00:00:00+00:00 [queued]>
[2023-08-22T16:08:55.963+0000] {taskinstance.py:1159} INFO - Dependencies all met for dep_context=requeueable deps ti=<TaskInstance: dag_with_taskflow_api_v02.greet scheduled__2022-01-26T00:00:00+00:00 [queued]>
[2023-08-22T16:08:55.964+0000] {taskinstance.py:1361} INFO - Starting attempt 1 of 6
[2023-08-22T16:08:56.151+0000] {taskinstance.py:1382} INFO - Executing <Task(_PythonDecoratedOperator): greet> on 2022-01-26 00:00:00+00:00
[2023-08-22T16:08:56.161+0000] {standard_task_runner.py:57} INFO - Started process 501 to run task
[2023-08-22T16:08:56.167+0000] {standard_task_runner.py:84} INFO - Running: ['***', 'tasks', 'run', 'dag_with_taskflow_api_v02', 'greet', 'scheduled__2022-01-26T00:00:00+00:00', '--job-id', '11963', '--raw', '--subdir', 'DAGS_FOLDER/dag_with_taskflow_api.py', '--cfg-path', '/tmp/tmpn4bk3aew']
[2023-08-22T16:08:56.170+0000] {standard_task_runner.py:85} INFO - Job 11963: Subtask greet
[2023-08-22T16:08:56.278+0000] {task_command.py:415} INFO - Running <TaskInstance: dag_with_taskflow_api_v02.greet scheduled__2022-01-26T00:00:00+00:00 [running]> on host b0ce6883e4a1
[2023-08-22T16:08:56.443+0000] {taskinstance.py:1660} INFO - Exporting env vars: AIRFLOW_CTX_DAG_OWNER='Techquier' AIRFLOW_CTX_DAG_ID='dag_with_taskflow_api_v02' AIRFLOW_CTX_TASK_ID='greet' AIRFLOW_CTX_EXECUTION_DATE='2022-01-26T00:00:00+00:00' AIRFLOW_CTX_TRY_NUMBER='1' AIRFLOW_CTX_DAG_RUN_ID='scheduled__2022-01-26T00:00:00+00:00'
[2023-08-22T16:08:56.450+0000] {taskinstance.py:1943} ERROR - Task failed with exception
Traceback (most recent call last):
  File "/home/airflow/.local/lib/python3.8/site-packages/airflow/decorators/base.py", line 221, in execute
    return_value = super().execute(context)
  File "/home/airflow/.local/lib/python3.8/site-packages/airflow/operators/python.py", line 192, in execute
    return_value = self.execute_callable()
  File "/home/airflow/.local/lib/python3.8/site-packages/airflow/operators/python.py", line 209, in execute_callable
    return self.python_callable(*self.op_args, **self.op_kwargs)
  File "/opt/airflow/dags/dag_with_taskflow_api.py", line 29, in greet
    print(f"Hello world! My name is {first_namename}{last_name}"
NameError: name 'first_namename' is not defined
[2023-08-22T16:08:56.478+0000] {taskinstance.py:1400} INFO - Marking task as UP_FOR_RETRY. dag_id=dag_with_taskflow_api_v02, task_id=greet, execution_date=20220126T000000, start_date=20230822T160855, end_date=20230822T160856
[2023-08-22T16:08:56.498+0000] {standard_task_runner.py:104} ERROR - Failed to execute job 11963 for task greet (name 'first_namename' is not defined; 501)
[2023-08-22T16:08:56.515+0000] {local_task_job_runner.py:228} INFO - Task exited with return code 1
[2023-08-22T16:08:56.538+0000] {taskinstance.py:2784} INFO - 0 downstream tasks scheduled from follow-on schedule check
