[2023-08-22T10:58:05.673+0000] {taskinstance.py:1159} INFO - Dependencies all met for dep_context=non-requeueable deps ti=<TaskInstance: dag_with_taskflow_api_v02.greet scheduled__2021-12-27T00:00:00+00:00 [queued]>
[2023-08-22T10:58:05.706+0000] {taskinstance.py:1159} INFO - Dependencies all met for dep_context=requeueable deps ti=<TaskInstance: dag_with_taskflow_api_v02.greet scheduled__2021-12-27T00:00:00+00:00 [queued]>
[2023-08-22T10:58:05.709+0000] {taskinstance.py:1361} INFO - Starting attempt 3 of 6
[2023-08-22T10:58:05.779+0000] {taskinstance.py:1382} INFO - Executing <Task(_PythonDecoratedOperator): greet> on 2021-12-27 00:00:00+00:00
[2023-08-22T10:58:05.808+0000] {standard_task_runner.py:57} INFO - Started process 34483 to run task
[2023-08-22T10:58:05.819+0000] {standard_task_runner.py:84} INFO - Running: ['***', 'tasks', 'run', 'dag_with_taskflow_api_v02', 'greet', 'scheduled__2021-12-27T00:00:00+00:00', '--job-id', '11720', '--raw', '--subdir', 'DAGS_FOLDER/dag_with_taskflow_api.py', '--cfg-path', '/tmp/tmpedqb6dyq']
[2023-08-22T10:58:05.834+0000] {standard_task_runner.py:85} INFO - Job 11720: Subtask greet
[2023-08-22T10:58:06.004+0000] {task_command.py:415} INFO - Running <TaskInstance: dag_with_taskflow_api_v02.greet scheduled__2021-12-27T00:00:00+00:00 [running]> on host b0ce6883e4a1
[2023-08-22T10:58:06.264+0000] {taskinstance.py:1660} INFO - Exporting env vars: AIRFLOW_CTX_DAG_OWNER='Techquier' AIRFLOW_CTX_DAG_ID='dag_with_taskflow_api_v02' AIRFLOW_CTX_TASK_ID='greet' AIRFLOW_CTX_EXECUTION_DATE='2021-12-27T00:00:00+00:00' AIRFLOW_CTX_TRY_NUMBER='3' AIRFLOW_CTX_DAG_RUN_ID='scheduled__2021-12-27T00:00:00+00:00'
[2023-08-22T10:58:06.267+0000] {taskinstance.py:1943} ERROR - Task failed with exception
Traceback (most recent call last):
  File "/home/airflow/.local/lib/python3.8/site-packages/airflow/decorators/base.py", line 221, in execute
    return_value = super().execute(context)
  File "/home/airflow/.local/lib/python3.8/site-packages/airflow/operators/python.py", line 192, in execute
    return_value = self.execute_callable()
  File "/home/airflow/.local/lib/python3.8/site-packages/airflow/operators/python.py", line 209, in execute_callable
    return self.python_callable(*self.op_args, **self.op_kwargs)
  File "/opt/airflow/dags/dag_with_taskflow_api.py", line 29, in greet
    print(f"Hello world! My name is {first_namename}{last_name}"
NameError: name 'first_namename' is not defined
[2023-08-22T10:58:06.307+0000] {taskinstance.py:1400} INFO - Marking task as UP_FOR_RETRY. dag_id=dag_with_taskflow_api_v02, task_id=greet, execution_date=20211227T000000, start_date=20230822T105805, end_date=20230822T105806
[2023-08-22T10:58:06.334+0000] {standard_task_runner.py:104} ERROR - Failed to execute job 11720 for task greet (name 'first_namename' is not defined; 34483)
[2023-08-22T10:58:06.370+0000] {local_task_job_runner.py:228} INFO - Task exited with return code 1
[2023-08-22T10:58:06.399+0000] {taskinstance.py:2784} INFO - 0 downstream tasks scheduled from follow-on schedule check
