[2023-08-23T09:26:51.124+0000] {taskinstance.py:1159} INFO - Dependencies all met for dep_context=non-requeueable deps ti=<TaskInstance: dag_with_taskflow_api_v02.greet scheduled__2022-07-07T00:00:00+00:00 [queued]>
[2023-08-23T09:26:51.143+0000] {taskinstance.py:1159} INFO - Dependencies all met for dep_context=requeueable deps ti=<TaskInstance: dag_with_taskflow_api_v02.greet scheduled__2022-07-07T00:00:00+00:00 [queued]>
[2023-08-23T09:26:51.144+0000] {taskinstance.py:1361} INFO - Starting attempt 3 of 6
[2023-08-23T09:26:51.166+0000] {taskinstance.py:1382} INFO - Executing <Task(_PythonDecoratedOperator): greet> on 2022-07-07 00:00:00+00:00
[2023-08-23T09:26:51.174+0000] {standard_task_runner.py:57} INFO - Started process 4973 to run task
[2023-08-23T09:26:51.183+0000] {standard_task_runner.py:84} INFO - Running: ['***', 'tasks', 'run', 'dag_with_taskflow_api_v02', 'greet', 'scheduled__2022-07-07T00:00:00+00:00', '--job-id', '13295', '--raw', '--subdir', 'DAGS_FOLDER/dag_with_taskflow_api.py', '--cfg-path', '/tmp/tmpffw7m12t']
[2023-08-23T09:26:51.186+0000] {standard_task_runner.py:85} INFO - Job 13295: Subtask greet
[2023-08-23T09:26:51.252+0000] {task_command.py:415} INFO - Running <TaskInstance: dag_with_taskflow_api_v02.greet scheduled__2022-07-07T00:00:00+00:00 [running]> on host b0ce6883e4a1
[2023-08-23T09:26:51.394+0000] {taskinstance.py:1660} INFO - Exporting env vars: AIRFLOW_CTX_DAG_OWNER='Techquier' AIRFLOW_CTX_DAG_ID='dag_with_taskflow_api_v02' AIRFLOW_CTX_TASK_ID='greet' AIRFLOW_CTX_EXECUTION_DATE='2022-07-07T00:00:00+00:00' AIRFLOW_CTX_TRY_NUMBER='3' AIRFLOW_CTX_DAG_RUN_ID='scheduled__2022-07-07T00:00:00+00:00'
[2023-08-23T09:26:51.396+0000] {taskinstance.py:1943} ERROR - Task failed with exception
Traceback (most recent call last):
  File "/home/airflow/.local/lib/python3.8/site-packages/airflow/decorators/base.py", line 221, in execute
    return_value = super().execute(context)
  File "/home/airflow/.local/lib/python3.8/site-packages/airflow/operators/python.py", line 192, in execute
    return_value = self.execute_callable()
  File "/home/airflow/.local/lib/python3.8/site-packages/airflow/operators/python.py", line 209, in execute_callable
    return self.python_callable(*self.op_args, **self.op_kwargs)
  File "/opt/airflow/dags/dag_with_taskflow_api.py", line 29, in greet
    print(f"Hello world! My name is {first_namename}{last_name}"
NameError: name 'first_namename' is not defined
[2023-08-23T09:26:51.415+0000] {taskinstance.py:1400} INFO - Marking task as UP_FOR_RETRY. dag_id=dag_with_taskflow_api_v02, task_id=greet, execution_date=20220707T000000, start_date=20230823T092651, end_date=20230823T092651
[2023-08-23T09:26:51.433+0000] {standard_task_runner.py:104} ERROR - Failed to execute job 13295 for task greet (name 'first_namename' is not defined; 4973)
[2023-08-23T09:26:51.474+0000] {local_task_job_runner.py:228} INFO - Task exited with return code 1
[2023-08-23T09:26:51.495+0000] {taskinstance.py:2784} INFO - 0 downstream tasks scheduled from follow-on schedule check
