[2023-08-22T08:09:23.028+0000] {taskinstance.py:1159} INFO - Dependencies all met for dep_context=non-requeueable deps ti=<TaskInstance: our_dag_with_python_opearator_v04.greet scheduled__2021-11-26T00:00:00+00:00 [queued]>
[2023-08-22T08:09:23.068+0000] {taskinstance.py:1159} INFO - Dependencies all met for dep_context=requeueable deps ti=<TaskInstance: our_dag_with_python_opearator_v04.greet scheduled__2021-11-26T00:00:00+00:00 [queued]>
[2023-08-22T08:09:23.070+0000] {taskinstance.py:1361} INFO - Starting attempt 2 of 6
[2023-08-22T08:09:23.109+0000] {taskinstance.py:1382} INFO - Executing <Task(PythonOperator): greet> on 2021-11-26 00:00:00+00:00
[2023-08-22T08:09:23.120+0000] {standard_task_runner.py:57} INFO - Started process 18847 to run task
[2023-08-22T08:09:23.128+0000] {standard_task_runner.py:84} INFO - Running: ['***', 'tasks', 'run', 'our_dag_with_python_opearator_v04', 'greet', 'scheduled__2021-11-26T00:00:00+00:00', '--job-id', '5672', '--raw', '--subdir', 'DAGS_FOLDER/create_dag_with_python_operator.py', '--cfg-path', '/tmp/tmpf6qec_t1']
[2023-08-22T08:09:23.134+0000] {standard_task_runner.py:85} INFO - Job 5672: Subtask greet
[2023-08-22T08:09:23.268+0000] {task_command.py:415} INFO - Running <TaskInstance: our_dag_with_python_opearator_v04.greet scheduled__2021-11-26T00:00:00+00:00 [running]> on host b0ce6883e4a1
[2023-08-22T08:09:23.558+0000] {taskinstance.py:1660} INFO - Exporting env vars: AIRFLOW_CTX_DAG_OWNER='coder2j' AIRFLOW_CTX_DAG_ID='our_dag_with_python_opearator_v04' AIRFLOW_CTX_TASK_ID='greet' AIRFLOW_CTX_EXECUTION_DATE='2021-11-26T00:00:00+00:00' AIRFLOW_CTX_TRY_NUMBER='2' AIRFLOW_CTX_DAG_RUN_ID='scheduled__2021-11-26T00:00:00+00:00'
[2023-08-22T08:09:23.564+0000] {taskinstance.py:1943} ERROR - Task failed with exception
Traceback (most recent call last):
  File "/home/airflow/.local/lib/python3.8/site-packages/airflow/operators/python.py", line 192, in execute
    return_value = self.execute_callable()
  File "/home/airflow/.local/lib/python3.8/site-packages/airflow/operators/python.py", line 209, in execute_callable
    return self.python_callable(*self.op_args, **self.op_kwargs)
  File "/opt/airflow/dags/create_dag_with_python_operator.py", line 11, in greet
    name = ti.xcoms_pull(task_ids='get_name')
AttributeError: 'TaskInstance' object has no attribute 'xcoms_pull'
[2023-08-22T08:09:23.630+0000] {taskinstance.py:1400} INFO - Marking task as UP_FOR_RETRY. dag_id=our_dag_with_python_opearator_v04, task_id=greet, execution_date=20211126T000000, start_date=20230822T080923, end_date=20230822T080923
[2023-08-22T08:09:23.672+0000] {standard_task_runner.py:104} ERROR - Failed to execute job 5672 for task greet ('TaskInstance' object has no attribute 'xcoms_pull'; 18847)
[2023-08-22T08:09:23.717+0000] {local_task_job_runner.py:228} INFO - Task exited with return code 1
[2023-08-22T08:09:23.751+0000] {taskinstance.py:2784} INFO - 0 downstream tasks scheduled from follow-on schedule check
